Workbook
Name _Int_3zCWM0Ms: 'categories 2'!#REF!

Sheet data
A1: DOI | B1: Authors | C1: Year | D1: Title | E1: Journal | F1: URL | G1: Citations | H1: Article per journal | I1: Study number | J1: General Notes | K1: Measure number | L1: Measure name | M1: How it is measured | N1: What is measured | O1: how-what alignment | P1: Used recent technology (only for 'what'=behavior) | Q1: Used as DV (only for 'what'=behavior) | R1: Measure notes
A2: 10.1016/j.brat.2022.104101 | B2: Hornstein; Eisenberger | C2: 2022 | D2: Exploring the effect of loneliness on fear: Implications for the effect of COVID-19-induced social disconnection on anxiety | E2: Behaviour Research and Therapy | F2: https://doi.org/10.1016/j.brat.2022.104101 | G2: 8 | H2: 1 | I2: 3 | K2: 1 | L2: Skin Conductance Response (SCR) Screening | M2: Neuro/bio/physiological | N2: Subjective experience | O2: =IF(OR(AND(data!M2='categories 2'!A$2,data!N2='categories 2'!B$2), AND(data!M2='categories 2'!A$3,data!N2='categories 2'!B$3), AND(data!M2='categories 2'!A$4,data!N2='categories 2'!B$4), AND(data!M2='categories 2'!A$5,data!N2='categories 2'!B$5)), "aligned", "MISALIGNED") -> MISALIGNED
I3: 3 | K3: 2 | L3: UCLA Loneliness Scale v3 (Russell, 1996) | M3: Self report | N3: Subjective experience | O3: =IF(OR(AND(data!M3='categories 2'!A$2,data!N3='categories 2'!B$2), AND(data!M3='categories 2'!A$3,data!N3='categories 2'!B$3), AND(data!M3='categories 2'!A$4,data!N3='categories 2'!B$4), AND(data!M3='categories 2'!A$5,data!N3='categories 2'!B$5)), "aligned", "MISALIGNED") -> aligned
A4: 10.1016/j.brat.2023.104456 | B4: Burger; Andikkhash; Jäger; Anderbro; Blanken; Klintwall | C4: 2024 | D4: A novel approach for constructing personalized networks from longitudinal perceived causal relations | E4: Behaviour Research and Therapy | F4: https://doi.org/10.1016/j.brat.2023.104456 | G4: 3 | H4: 2 | I4: 1 | K4: 1 | L4: PHQ-9 (Kroenke et al., 2001) | M4: Self report | N4: Subjective experience | O4: =IF(OR(AND(data!M4='categories 2'!A$2,data!N4='categories 2'!B$2), AND(data!M4='categories 2'!A$3,data!N4='categories 2'!B$3), AND(data!M4='categories 2'!A$4,data!N4='categories 2'!B$4), AND(data!M4='categories 2'!A$5,data!N4='categories 2'!B$5)), "aligned", "MISALIGNED") -> aligned
I5: 1 | K5: 2 | L5: Daily assessments of L-PECAN (Klintwall et al., 2023) | M5: Self report | N5: Indeterminable | O5: =IF(OR(AND(data!M5='categories 2'!A$2,data!N5='categories 2'!B$2), AND(data!M5='categories 2'!A$3,data!N5='categories 2'!B$3), AND(data!M5='categories 2'!A$4,data!N5='categories 2'!B$4), AND(data!M5='categories 2'!A$5,data!N5='categories 2'!B$5)), "aligned", "MISALIGNED") -> MISALIGNED
A6: 10.1111/cdev.13157 | B6: Elenbaas | C6: 2019 | D6: Interwealth Contact and Young Children's Concern for Equity | E6: Child Development | F6: https://doi.org/10.1111/cdev.13157 | G6: 17 | H6: 1 | I6: 1 | K6: 1 | L6: Unnamed questions: "Wealth Preference and Perceptions" | M6: Self report | N6: Subjective experience | O6: =IF(OR(AND(data!M6='categories 2'!A$2,data!N6='categories 2'!B$2), AND(data!M6='categories 2'!A$3,data!N6='categories 2'!B$3), AND(data!M6='categories 2'!A$4,data!N6='categories 2'!B$4), AND(data!M6='categories 2'!A$5,data!N6='categories 2'!B$5)), "aligned", "MISALIGNED") -> aligned
I7: 1 | K7: 2 | L7: Unnamed Task: "Resource Allocation" | M7: Behavioral (frequency, duration, latency) | N7: Behavior | O7: =IF(OR(AND(data!M7='categories 2'!A$2,data!N7='categories 2'!B$2), AND(data!M7='categories 2'!A$3,data!N7='categories 2'!B$3), AND(data!M7='categories 2'!A$4,data!N7='categories 2'!B$4), AND(data!M7='categories 2'!A$5,data!N7='categories 2'!B$5)), "aligned", "MISALIGNED") -> aligned | P7: FALSE | Q7: Out of time
I8: 1 | K8: 3 | L8: Reasoning About Resource Allocation | M8: Self report | N8: Subjective experience | O8: =IF(OR(AND(data!M8='categories 2'!A$2,data!N8='categories 2'!B$2), AND(data!M8='categories 2'!A$3,data!N8='categories 2'!B$3), AND(data!M8='categories 2'!A$4,data!N8='categories 2'!B$4), AND(data!M8='categories 2'!A$5,data!N8='categories 2'!B$5)), "aligned", "MISALIGNED") -> aligned
I9: 1 | K9: 4 | L9: Unnamed questions: "Inter and Intra-wealth Contact" | M9: Self report | N9: Indeterminable | O9: =IF(OR(AND(data!M9='categories 2'!A$2,data!N9='categories 2'!B$2), AND(data!M9='categories 2'!A$3,data!N9='categories 2'!B$3), AND(data!M9='categories 2'!A$4,data!N9='categories 2'!B$4), AND(data!M9='categories 2'!A$5,data!N9='categories 2'!B$5)), "aligned", "MISALIGNED") -> MISALIGNED
A10: 10.1111/j.1467-8624.2012.01817.x | B10: Bascoe; Davies; Cummings | C10: 2012 | D10: Beyond Warmth and Conflict: The Developmental Utility of a Boundary Conceptualization of Sibling Relationship Processes | E10: Child Development | F10: https://doi.org/10.1111/j.1467-8624.2012.01817.x | G10: 17 | H10: 2 | I10: 1 | K10: 1 | L10: Emotional Symptoms subscale from the Self-Report Strengths and Difficulties Questionnaire (SDQ, Goodman, 2001) | M10: Self report | N10: Subjective experience | O10: =IF(OR(AND(data!M10='categories 2'!A$2,data!N10='categories 2'!B$2), AND(data!M10='categories 2'!A$3,data!N10='categories 2'!B$3), AND(data!M10='categories 2'!A$4,data!N10='categories 2'!B$4), AND(data!M10='categories 2'!A$5,data!N10='categories 2'!B$5)), "aligned", "MISALIGNED") -> aligned
I11: 1 | J11: Subjective, behavioral and physiological items! | K11: 2 | L11: Total Anxiety scale from the Revised Child Manifest Anxiety Scale (RCMAS) | M11: Self report | N11: Neuro/bio/physiology | O11: =IF(OR(AND(data!M11='categories 2'!A$2,data!N11='categories 2'!B$2), AND(data!M11='categories 2'!A$3,data!N11='categories 2'!B$3), AND(data!M11='categories 2'!A$4,data!N11='categories 2'!B$4), AND(data!M11='categories 2'!A$5,data!N11='categories 2'!B$5)), "aligned", "MISALIGNED") -> MISALIGNED
I12: 1 | K12: 3 | L12: Center for Epidemiological Studies Depression Scale (CES-D) | M12: Self report | N12: Behavior | O12: =IF(OR(AND(data!M12='categories 2'!A$2,data!N12='categories 2'!B$2), AND(data!M12='categories 2'!A$3,data!N12='categories 2'!B$3), AND(data!M12='categories 2'!A$4,data!N12='categories 2'!B$4), AND(data!M12='categories 2'!A$5,data!N12='categories 2'!B$5)), "aligned", "MISALIGNED") -> MISALIGNED | P12: FALSE | Q12: TRUE
I13: 1 | K13: 4 | L13: Delinquent scales from the respective Teacher Report Form and Child Behavior Checklist instruments (Achenbach, 1991) | M13: Self report | N13: Behavior | O13: =IF(OR(AND(data!M13='categories 2'!A$2,data!N13='categories 2'!B$2), AND(data!M13='categories 2'!A$3,data!N13='categories 2'!B$3), AND(data!M13='categories 2'!A$4,data!N13='categories 2'!B$4), AND(data!M13='categories 2'!A$5,data!N13='categories 2'!B$5)), "aligned", "MISALIGNED") -> MISALIGNED | P13: FALSE | Q13: TRUE
I14: 1 | K14: 5 | L14: Conduct Problems subscale of the SDQ | M14: Self report | N14: Behavior | O14: =IF(OR(AND(data!M14='categories 2'!A$2,data!N14='categories 2'!B$2), AND(data!M14='categories 2'!A$3,data!N14='categories 2'!B$3), AND(data!M14='categories 2'!A$4,data!N14='categories 2'!B$4), AND(data!M14='categories 2'!A$5,data!N14='categories 2'!B$5)), "aligned", "MISALIGNED") -> MISALIGNED | P14: FALSE | Q14: TRUE
I15: 1 | K15: 6 | L15: Social Problems subscales of the CBCL questionnaire | M15: Self report | N15: Behavior | O15: =IF(OR(AND(data!M15='categories 2'!A$2,data!N15='categories 2'!B$2), AND(data!M15='categories 2'!A$3,data!N15='categories 2'!B$3), AND(data!M15='categories 2'!A$4,data!N15='categories 2'!B$4), AND(data!M15='categories 2'!A$5,data!N15='categories 2'!B$5)), "aligned", "MISALIGNED") -> MISALIGNED | P15: Out of time | Q15: Out of time
I16: 1 | K16: 7 | L16: Social Problems subscales of the TRF questionnaire | M16: Self report | N16: Behavior | O16: =IF(OR(AND(data!M16='categories 2'!A$2,data!N16='categories 2'!B$2), AND(data!M16='categories 2'!A$3,data!N16='categories 2'!B$3), AND(data!M16='categories 2'!A$4,data!N16='categories 2'!B$4), AND(data!M16='categories 2'!A$5,data!N16='categories 2'!B$5)), "aligned", "MISALIGNED") -> MISALIGNED | P16: Out of time | Q16: Out of time
A17: 10.1177/2167702613484717 | B17: Schueller; Pérez-Stable; Muñoz | C17: 2013 | D17: A Mood Management Intervention in an Internet Stop Smoking Randomized Controlled Trial Does Not Prevent Depression | E17: Clinical Psychological Science | F17: https://doi.org/10.1177/2167702613484717 | G17: 4 | H17: 1 | I17: 1 | K17: 1 | L17: MDE Screener (Muñoz, 1998) | M17: Self report | N17: Behavior | O17: =IF(OR(AND(data!M17='categories 2'!A$2,data!N17='categories 2'!B$2), AND(data!M17='categories 2'!A$3,data!N17='categories 2'!B$3), AND(data!M17='categories 2'!A$4,data!N17='categories 2'!B$4), AND(data!M17='categories 2'!A$5,data!N17='categories 2'!B$5)), "aligned", "MISALIGNED") -> MISALIGNED | P17: FALSE | Q17: TRUE
I18: 1 | K18: 2 | L18: Center for Epidemiologic Studies Depression Scale (CESD; Radloff, 1977) | M18: Self report | N18: Behavior | O18: =IF(OR(AND(data!M18='categories 2'!A$2,data!N18='categories 2'!B$2), AND(data!M18='categories 2'!A$3,data!N18='categories 2'!B$3), AND(data!M18='categories 2'!A$4,data!N18='categories 2'!B$4), AND(data!M18='categories 2'!A$5,data!N18='categories 2'!B$5)), "aligned", "MISALIGNED") -> MISALIGNED | P18: FALSE | Q18: TRUE
I19: 1 | K19: 3 | L19: Website utilization | M19: Behavioral (frequency, duration, latency) | N19: Behavior | O19: =IF(OR(AND(data!M19='categories 2'!A$2,data!N19='categories 2'!B$2), AND(data!M19='categories 2'!A$3,data!N19='categories 2'!B$3), AND(data!M19='categories 2'!A$4,data!N19='categories 2'!B$4), AND(data!M19='categories 2'!A$5,data!N19='categories 2'!B$5)), "aligned", "MISALIGNED") -> aligned | P19: TRUE | Q19: Out of time
A20: 10.1177/2167702614553026 | B20: Lane; Sher | C20: 2015 | D20: Limits of Current Approaches to Diagnosis Severity Based on Criterion Counts | E20: Clinical Psychological Science | F20: https://doi.org/10.1177/2167702614553026 | G20: 68 | H20: 2 | I20: 1 | J20: Structured Interview | K20: 1 | L20: AUD Criteria (Alcohol Use Disorder and Associated Disabilities Interview Schedule-IV; Grant et al., 2003) | M20: Self report | N20: Behavior | O20: =IF(OR(AND(data!M20='categories 2'!A$2,data!N20='categories 2'!B$2), AND(data!M20='categories 2'!A$3,data!N20='categories 2'!B$3), AND(data!M20='categories 2'!A$4,data!N20='categories 2'!B$4), AND(data!M20='categories 2'!A$5,data!N20='categories 2'!B$5)), "aligned", "MISALIGNED") -> MISALIGNED | P20: FALSE | Q20: FALSE
I21: 1 | K21: 2 | L21: Drinking behavior (Dawson et al., 2005) | M21: Self report | N21: Behavior | O21: =IF(OR(AND(data!M21='categories 2'!A$2,data!N21='categories 2'!B$2), AND(data!M21='categories 2'!A$3,data!N21='categories 2'!B$3), AND(data!M21='categories 2'!A$4,data!N21='categories 2'!B$4), AND(data!M21='categories 2'!A$5,data!N21='categories 2'!B$5)), "aligned", "MISALIGNED") -> MISALIGNED | P21: FALSE | Q21: TRUE
I22: 1 | K22: 3 | L22: Measure of overall health and wellbeing, constructed from the SF12-V2 physical and mental functioning scales | M22: Self report | N22: Neuro/bio/physiology | O22: =IF(OR(AND(data!M22='categories 2'!A$2,data!N22='categories 2'!B$2), AND(data!M22='categories 2'!A$3,data!N22='categories 2'!B$3), AND(data!M22='categories 2'!A$4,data!N22='categories 2'!B$4), AND(data!M22='categories 2'!A$5,data!N22='categories 2'!B$5)), "aligned", "MISALIGNED") -> MISALIGNED
I23: 1 | K23: 4 | L23: Lifetime Axis I and Axis II Diagnoses | M23: Self report | N23: Indeterminable | O23: =IF(OR(AND(data!M23='categories 2'!A$2,data!N23='categories 2'!B$2), AND(data!M23='categories 2'!A$3,data!N23='categories 2'!B$3), AND(data!M23='categories 2'!A$4,data!N23='categories 2'!B$4), AND(data!M23='categories 2'!A$5,data!N23='categories 2'!B$5)), "aligned", "MISALIGNED") -> MISALIGNED
A24: 10.1016/j.cognition.2013.01.010 | B24: Wagner; Dobkins; Barner | C24: 2013 | D24: Slow mapping: Color word learning as a gradual inductive process | E24: Cognition | F24: https://doi.org/10.1016/j.cognition.2013.01.010 | G24: 34 | H24: 1 | I24: 1 | K24: 1 | L24: Fish task | M24: Behavioral (frequency, duration, latency) | N24: Mental ability or cognitive process | O24: =IF(OR(AND(data!M24='categories 2'!A$2,data!N24='categories 2'!B$2), AND(data!M24='categories 2'!A$3,data!N24='categories 2'!B$3), AND(data!M24='categories 2'!A$4,data!N24='categories 2'!B$4), AND(data!M24='categories 2'!A$5,data!N24='categories 2'!B$5)), "aligned", "MISALIGNED") -> MISALIGNED
I25: 1 | K25: 2 | L25: Book task | M25: Behavioral (frequency, duration, latency) | N25: Mental ability or cognitive process | O25: =IF(OR(AND(data!M25='categories 2'!A$2,data!N25='categories 2'!B$2), AND(data!M25='categories 2'!A$3,data!N25='categories 2'!B$3), AND(data!M25='categories 2'!A$4,data!N25='categories 2'!B$4), AND(data!M25='categories 2'!A$5,data!N25='categories 2'!B$5)), "aligned", "MISALIGNED") -> MISALIGNED
A26: 10.1016/j.cognition.2024.106051 | B26: Finiasz; Shore; Xu; Kushnir | C26: 2025 | D26: Children's cost-benefit analysis about agents who act for the greater good | E26: Cognition | F26: https://doi.org/10.1016/j.cognition.2024.106051 | G26: 0 | H26: 2 | I26: 2 | K26: 1 | L26: Prediction Question (likert scale) | M26: Self report | N26: Subjective experience | O26: =IF(OR(AND(data!M26='categories 2'!A$2,data!N26='categories 2'!B$2), AND(data!M26='categories 2'!A$3,data!N26='categories 2'!B$3), AND(data!M26='categories 2'!A$4,data!N26='categories 2'!B$4), AND(data!M26='categories 2'!A$5,data!N26='categories 2'!B$5)), "aligned", "MISALIGNED") -> aligned
I27: 2 | K27: 2 | L27: Permissibility Judgment (likert scale) | M27: Self report | N27: Subjective experience | O27: =IF(OR(AND(data!M27='categories 2'!A$2,data!N27='categories 2'!B$2), AND(data!M27='categories 2'!A$3,data!N27='categories 2'!B$3), AND(data!M27='categories 2'!A$4,data!N27='categories 2'!B$4), AND(data!M27='categories 2'!A$5,data!N27='categories 2'!B$5)), "aligned", "MISALIGNED") -> aligned
A28: 10.1525/collabra.128470 | B28: Sato; Gygax; Gabriel; Oakhill; Escasain | C28: 2025 | D28: Does Inclusive Language Increase the Visibility of Women, or Does It Simply Decrease the Visibility of Men? A Missing Piece of the Inclusive Language Jigsaw | E28: Collabra: Psychology | F28: https://doi.org/10.1525/collabra.128470 | G28: 2 | H28: 1 | I28: 1 | K28: 1 | L28: Unnamed questionnaire: Estimating the distribution of women and men in occupations | M28: Self report | N28: Subjective experience | O28: =IF(OR(AND(data!M28='categories 2'!A$2,data!N28='categories 2'!B$2), AND(data!M28='categories 2'!A$3,data!N28='categories 2'!B$3), AND(data!M28='categories 2'!A$4,data!N28='categories 2'!B$4), AND(data!M28='categories 2'!A$5,data!N28='categories 2'!B$5)), "aligned", "MISALIGNED") -> aligned
A29: 10.1525/collabra.117083 | B29: Folk; Yu; Dunn | C29: 2024 | D29: Can Chatbots Ever Provide More Social Connection Than Humans? | E29: Collabra: Psychology | F29: https://doi.org/10.1525/collabra.117083 | G29: 0 | H29: 2 | I29: 2 | K29: 1 | L29: Social connection single-item (created for this study) | M29: Self report | N29: Subjective experience | O29: =IF(OR(AND(data!M29='categories 2'!A$2,data!N29='categories 2'!B$2), AND(data!M29='categories 2'!A$3,data!N29='categories 2'!B$3), AND(data!M29='categories 2'!A$4,data!N29='categories 2'!B$4), AND(data!M29='categories 2'!A$5,data!N29='categories 2'!B$5)), "aligned", "MISALIGNED") -> aligned
I30: 2 | K30: 2 | L30: Positive affect SPANE (Diener et al., 2009) | M30: Self report | N30: Subjective experience | O30: =IF(OR(AND(data!M30='categories 2'!A$2,data!N30='categories 2'!B$2), AND(data!M30='categories 2'!A$3,data!N30='categories 2'!B$3), AND(data!M30='categories 2'!A$4,data!N30='categories 2'!B$4), AND(data!M30='categories 2'!A$5,data!N30='categories 2'!B$5)), "aligned", "MISALIGNED") -> aligned
I31: 2 | K31: 3 | L31: Feelings about experience (created for this study) | M31: Self report | N31: Subjective experience | O31: =IF(OR(AND(data!M31='categories 2'!A$2,data!N31='categories 2'!B$2), AND(data!M31='categories 2'!A$3,data!N31='categories 2'!B$3), AND(data!M31='categories 2'!A$4,data!N31='categories 2'!B$4), AND(data!M31='categories 2'!A$5,data!N31='categories 2'!B$5)), "aligned", "MISALIGNED") -> aligned
I32: 2 | K32: 4 | L32: Perceived Agency (Epley et al., 2008) | M32: Self report | N32: Subjective experience | O32: =IF(OR(AND(data!M32='categories 2'!A$2,data!N32='categories 2'!B$2), AND(data!M32='categories 2'!A$3,data!N32='categories 2'!B$3), AND(data!M32='categories 2'!A$4,data!N32='categories 2'!B$4), AND(data!M32='categories 2'!A$5,data!N32='categories 2'!B$5)), "aligned", "MISALIGNED") -> aligned
A33: 10.1037/dev0000712 | B33: Brod; Shing | C33: 2019 | D33: A boon and a bane: Comparing the effects of prior knowledge on memory across the lifespan. | E33: Developmental Psychology | F33: https://doi.org/10.1037/dev0000712 | G33: 38 | H33: 1 | I33: 1 | K33: 1 | L33: Congruency judgement test | M33: Test | N33: Mental ability or cognitive process | O33: =IF(OR(AND(data!M33='categories 2'!A$2,data!N33='categories 2'!B$2), AND(data!M33='categories 2'!A$3,data!N33='categories 2'!B$3), AND(data!M33='categories 2'!A$4,data!N33='categories 2'!B$4), AND(data!M33='categories 2'!A$5,data!N33='categories 2'!B$5)), "aligned", "MISALIGNED") -> aligned
I34: 1 | K34: 2 | L34: Memory test | M34: Test | N34: Mental ability or cognitive process | O34: =IF(OR(AND(data!M34='categories 2'!A$2,data!N34='categories 2'!B$2), AND(data!M34='categories 2'!A$3,data!N34='categories 2'!B$3), AND(data!M34='categories 2'!A$4,data!N34='categories 2'!B$4), AND(data!M34='categories 2'!A$5,data!N34='categories 2'!B$5)), "aligned", "MISALIGNED") -> aligned
I35: 1 | K35: 3 | L35: fMRI | M35: Neuro/bio/physiological | N35: Mental ability or cognitive process | O35: =IF(OR(AND(data!M35='categories 2'!A$2,data!N35='categories 2'!B$2), AND(data!M35='categories 2'!A$3,data!N35='categories 2'!B$3), AND(data!M35='categories 2'!A$4,data!N35='categories 2'!B$4), AND(data!M35='categories 2'!A$5,data!N35='categories 2'!B$5)), "aligned", "MISALIGNED") -> MISALIGNED
A36: 10.1037/dev0000374 | B36: Becht; Nelemans; Branje; Vollebergh; Koot; Meeus | C36: 2017 | D36: Identity uncertainty and commitment making across adolescence: Five-year within-person associations using daily identity reports. | E36: Developmental Psychology | F36: https://doi.org/10.1037/dev0000374 | G36: 37 | H36: 2 | I36: 1 | K36: 1 | L36: Utrecht-Management of Identity Commitments Scale (U-MICS; Klimstra et al., 2010); Single item | M36: Self report | N36: Subjective experience | O36: =IF(OR(AND(data!M36='categories 2'!A$2,data!N36='categories 2'!B$2), AND(data!M36='categories 2'!A$3,data!N36='categories 2'!B$3), AND(data!M36='categories 2'!A$4,data!N36='categories 2'!B$4), AND(data!M36='categories 2'!A$5,data!N36='categories 2'!B$5)), "aligned", "MISALIGNED") -> aligned
A37: 10.1037/emo0000021 | B37: Tamir; Bigman; Rhodes; Salerno; Schreier | C37: 2015 | D37: An expectancy-value model of emotion regulation: Implications for motivation, emotional experience, and decision making. | E37: Emotion | F37: https://doi.org/10.1037/emo0000021 | G37: 89 | H37: 1 | I37: 1 | K37: 1 | L37: Unnamed rating of concurrent emotions | M37: Self report | N37: Subjective experience | O37: =IF(OR(AND(data!M37='categories 2'!A$2,data!N37='categories 2'!B$2), AND(data!M37='categories 2'!A$3,data!N37='categories 2'!B$3), AND(data!M37='categories 2'!A$4,data!N37='categories 2'!B$4), AND(data!M37='categories 2'!A$5,data!N37='categories 2'!B$5)), "aligned", "MISALIGNED") -> aligned
I38: 1 | K38: 2 | L38: Unnamed rating of reading preference | M38: Self report | N38: Subjective experience | O38: =IF(OR(AND(data!M38='categories 2'!A$2,data!N38='categories 2'!B$2), AND(data!M38='categories 2'!A$3,data!N38='categories 2'!B$3), AND(data!M38='categories 2'!A$4,data!N38='categories 2'!B$4), AND(data!M38='categories 2'!A$5,data!N38='categories 2'!B$5)), "aligned", "MISALIGNED") -> aligned
A39: 10.1037/emo0001057 | B39: Lee; Lim; Lee | C39: 2022 | D39: Sharing joy increases joy: Group membership modulates emotional perception of facial expressions. | E39: Emotion | F39: https://doi.org/10.1037/emo0001057 | G39: 1 | H39: 2 | I39: 2 | K39: 1 | L39: Unnamed win/loss judgment task | M39: Test | N39: Mental ability or cognitive process | O39: =IF(OR(AND(data!M39='categories 2'!A$2,data!N39='categories 2'!B$2), AND(data!M39='categories 2'!A$3,data!N39='categories 2'!B$3), AND(data!M39='categories 2'!A$4,data!N39='categories 2'!B$4), AND(data!M39='categories 2'!A$5,data!N39='categories 2'!B$5)), "aligned", "MISALIGNED") -> aligned
I40: 2 | K40: 2 | L40: Unnamed emotional judgment task | M40: Self report | N40: Subjective experience | O40: =IF(OR(AND(data!M40='categories 2'!A$2,data!N40='categories 2'!B$2), AND(data!M40='categories 2'!A$3,data!N40='categories 2'!B$3), AND(data!M40='categories 2'!A$4,data!N40='categories 2'!B$4), AND(data!M40='categories 2'!A$5,data!N40='categories 2'!B$5)), "aligned", "MISALIGNED") -> aligned
...

Sheet categories
A1: category | B1: example
A2: Self-report of subjective experience | B2: Self-reported fear of spiders
A3: Subjective experience test | B3: Visual search test for synesthesia
A4: Behavioral measure of subjective experience | B4: Implicit racial bias
A5: Neuro/bio/physiological measure of subjective experience | B5: GSR as a measure of fear
A6: Self-report of ability | B6: Self-reported intelligence, self-reported empathic perspective taking ability
A7: Cognitive ability test | B7: Mental rotation test, N-back task
A8: Behavioral measure of ability | B8: Iowa Gambling Task
A9: Neuro/bio/physiological measure of ability | B9: Cognitive Control Capacity measured via fMRI
A10: Self-report of behavior | B10: Self-reported social media use
A11: Behavioral test | B11: Stimulus equivalence test
A12: Behavioral measure of behavior | B12: Social media use via digital trace data, observational coding
... A17: Neuro/bio/physiological measure of neuro/bio/physiology | B17: Structural MRI, Salivatory immunoassays to measure menstrual cycle phase
A18: Indeterminable

Sheet categories 2
A1: How it is measured | B1: What is measured | C1: Boolean | D1: Alignment
A2: Self report | B2: Subjective experience | C2: TRUE | D2: aligned
A3: Test | B3: Mental ability or cognitive process | C3: FALSE | D3: MISALIGNED
A4: Behavioral (frequency, duration, latency) | B4: Behavior | C4: Indeterminable
A5: Neuro/bio/physiological | B5: Neuro/bio/physiology | C5: Out of time
A6: Indeterminable | B6: Indeterminable
A7: Out of time | B7: Out of time
A11: old
A12: Self-report or other report | B12: Subjective experience (mental content, often self-perceived)
A13: Test (has correct answers) | B13: Mental ability or cognitive process
A14: Behavioral measure (non-self-report; captures frequency, duration or latency of overt behaviors) | B14: Behavior (specific overt behaviors)
A15: Neuro/bio/physiological measure | B15: Neuro/bio/physiology
A16: Indeterminable | B16: Indeterminable
